<?xml version="1.0" encoding="utf-8"?>
<robot name="ur5e">

  <link name="base_link">
    <visual>
      <origin xyz="0 0 0" rpy="0 0 0" />
      <geometry>
        <mesh filename="file://./configs/meshes/ur5e/base.dae" />
      </geometry>
      <material name="">
        <color rgba="0.79216 0.81961 0.93333 1" />
      </material>
    </visual>
  </link>

  <link name="link1">
    <visual>
      <origin xyz="0 0 0.0634" rpy="0 0 3.141592653589793" />
      <geometry>
        <mesh filename="file://./configs/meshes/ur5e/shoulder.dae" />
      </geometry>
      <material name="">
        <color rgba="0.79216 0.81961 0.93333 1" />
      </material>
    </visual>
  </link>

  <joint name="joint1" type="revolute">
    <origin xyz="0 0 0.0991" rpy="0 0 3.1416" />
    <parent link="base_link" />
    <child link="link1" />
    <axis xyz="0 0 1" />
    <limit lower="-3.14" upper="3.14" effort="100" velocity="3.14" />
  </joint>

  <link name="link2">
    <visual>
      <origin xyz="0 0 0.139" rpy="1.5708 0 -1.5708" />
      <geometry>
        <mesh filename="file://./configs/meshes/ur5e/upperarm.dae" />
      </geometry>
      <material name="">
        <color rgba="0.79216 0.81961 0.93333 1" />
      </material>
    </visual>
  </link>

  <joint name="joint2" type="revolute">
    <origin xyz="0 0 0.0634" rpy="1.5708 0 0" />
    <parent link="link1" />
    <child link="link2" />
    <axis xyz="0 0 1" />
    <limit lower="-3.14" upper="3.14" effort="100" velocity="3.14" />
  </joint>

  <link name="link3">
    <visual>
      <origin xyz="0 0 0.00997" rpy="1.5708 0 -1.5708" />
      <geometry>
        <mesh filename="file://./configs/meshes/ur5e/forearm.dae" />
      </geometry>
      <material name="">
        <color rgba="0.79216 0.81961 0.93333 1" />
      </material>
    </visual>
  </link>

  <joint name="joint3" type="revolute">
    <origin xyz="-0.425 0 0" rpy="0 0 0" />
    <parent link="link2" />
    <child link="link3" />
    <axis xyz="0 0 1" />
    <limit lower="-3.14" upper="3.14" effort="100" velocity="3.14" />
  </joint>

  <link name="link4">
    <visual>
      <origin xyz="0 0 0.007" rpy="1.5708 0 0" />
      <geometry>
        <mesh filename="file://./configs/meshes/ur5e/wrist1.dae" />
      </geometry>
      <material name="">
        <color rgba="0.79216 0.81961 0.93333 1" />
      </material>
    </visual>
  </link>

  <joint name="joint4" type="revolute">
    <origin xyz="-0.3922 0 0" rpy="0 0 0" />
    <parent link="link3" />
    <child link="link4" />
    <axis xyz="0 0 1" />
    <limit lower="-3.14" upper="3.14" effort="100" velocity="3.14" />
  </joint>

  <link name="link5">
    <visual>
      <origin xyz="0 0 0" rpy="0 0 0" />
      <geometry>
        <mesh filename="file://./configs/meshes/ur5e/wrist2.dae" />
      </geometry>
      <material name="">
        <color rgba="0.79216 0.81961 0.93333 1" />
      </material>
    </visual>
  </link>

  <joint name="joint5" type="revolute">
    <origin xyz="0 0 0.1333" rpy="1.5708 0 0" />
    <parent link="link4" />
    <child link="link5" />
    <axis xyz="0 0 1" />
    <limit lower="-3.14" upper="3.14" effort="100" velocity="3.14" />
  </joint>

  <link name="link6">
    <visual>
      <origin xyz="1.28 0.204 -0.133" rpy="1.5708 0 -1.5708" />
      <geometry>
        <mesh filename="file://./configs/meshes/ur5e/ee-and-drill-mesh-Demo-0228-Chen-cad-in-mm-stl-gen-in-m.STL" scale="1 1 1" />
      </geometry>
      <material name="">
        <color rgba="0.79216 0.81961 0.93333 1" />
      </material>
    </visual>
  </link>

  <joint name="joint6" type="revolute">
    <origin xyz="0 0 0.0997" rpy="-1.5708 0 0" />
    <parent link="link5" />
    <child link="link6" />
    <axis xyz="0 0 1" />
    <limit lower="-3.14" upper="3.14" effort="100" velocity="3.14" />
  </joint>

  <link name="articulated_joint_link">
    <visual>
      <origin xyz="-0.0015 -0.002 -0.004" rpy="0 0 0" />
      <!-- <origin xyz="0.02 -0.002 -0.004" rpy="0 0 0" /> -->
      <geometry>
        <mesh filename="file://./configs/meshes/ur5e/joint_tip.STL" scale="0.001 0.001 0.001" />
      </geometry>
      <material name="">
        <color rgba="0.89804 0.91765 0.92941 1" />
      </material>
    </visual>
  </link>

  <joint name="articulated_joint" type="revolute">
    <origin xyz="0 -0.1696 0.2456" rpy="0 -1.5708 0.0" />
    <parent link="link6" />
    <child link="articulated_joint_link" />
    <axis xyz="0 0 1" />
    <limit lower="0.0001" upper="0.7845" effort="10" velocity="1" />
  </joint>

  <!-- fixed link for reference -->
  <link name="tool_tip"></link>
  <joint name="tip_joint" type="fixed">
    <origin xyz="0.0174 0.0152 0" rpy="0.0 -1.5708 -1.5708" />
    <parent link="articulated_joint_link" />
    <child link="tool_tip" />
    <axis xyz="0 0 0" />
  </joint>

  <link name="tool_handle"></link>
  <joint name="handle_fixed_joint" type="fixed">
    <origin xyz="0 -0.15875 0.0151" rpy="0 0 0" />
    <parent link="link6" />
    <child link="tool_handle" />
    <axis xyz="0 0 0" />
  </joint>

  <link name="cnl_link"></link>
  <joint name="cnl_fixed_joint" type="fixed">
    <origin xyz="0 -0.1675 0.2641" rpy="0 0 0" />
    <parent link="link6" />
    <child link="cnl_link" />
    <axis xyz="0 0 0" />
  </joint>

  <link name="ft_sensor_link"></link>
  <joint name="ft_handle_fixed_joint" type="fixed">
    <origin xyz="0 -0.0695 0.0746" rpy="1.57079632679 -1.57079632679 0.0" />
    <parent link="link6" />
    <child link="ft_sensor_link" />
    <axis xyz="0 0 0" />
  </joint>
  <!-- fixed link for reference -->

</robot>
